<?xml version="1.0"?>
<robot name="wheel" xmlns:xacro="http://www.ros.org/wiki/xacro">
  
  <xacro:macro name="wheel" params="lr parent translateX translateY flipY"> <!--lr: left, right -->
    <link name="${lr}_wheel">
      <visual>
        <origin xyz="0 0 0" rpy="${flipY*pi/2} 0  0 " /> 
        <geometry>
          <cylinder length="${wheel_thickness}" radius="${wheel_radius}" />
        </geometry>
        <material name="DarkGray" />
      </visual>
      <collision>
        <origin xyz="0 0 0" rpy="${flipY*pi/2} 0 0 " />
        <geometry>
          <cylinder length="${wheel_thickness}" radius="${wheel_radius}" />
        </geometry>
      </collision>
      <inertial>
        <mass value="${motor_wheel_mass}" />
        <origin xyz="0 0 0" />
        <cylinder_inertia  m="${motor_wheel_mass}" r="${wheel_radius}" h="${wheel_thickness}" />
      </inertial>
    </link>

    <gazebo reference="${lr}_wheel">
      <mu1 value="1.0"/>
      <mu2 value="1.0"/>
      <kp  value="10000000.0" />
      <kd  value="1.0" />
      <fdir1 value="1 0 0"/>
      <material>Gazebo/Grey</material>
      <turnGravityOff>false</turnGravityOff>
    </gazebo>

    <joint name="${lr}_wheel_joint" type="continuous">
      <parent link="${parent}"/>
      <child link="${lr}_wheel"/>
      <origin xyz="${translateX * base_x_origin_to_wheel_origin} ${translateY * base_y_origin_to_wheel_origin} ${base_z_origin_to_wheel_origin}" rpy="0 0 0" /> 
      <axis xyz="0 1 0" rpy="0  0" />
      <joint_properties damping="0.0" friction="0.0"/>
    </joint>

    <!-- Transmission is important to link the joints and the controller -->
    <transmission name="${lr}_wheel_joint_trans">
      <type>transmission_interface/SimpleTransmission</type>
      <actuator name="${lr}_wheel_motor">
        <mechanicalReduction>1</mechanicalReduction>
      </actuator>
      <joint name="${lr}_wheel_joint">
        <hardwareInterface>VelocityJointInterface</hardwareInterface>
      </joint>
    </transmission>
   
  </xacro:macro>
</robot>
